<?xml version="1.0" ?>
<!-- =================================================================================== -->
<!-- |    This document was autogenerated by xacro from second_goat_robot.urdf.xacro   | -->
<!-- |    EDITING THIS FILE BY HAND IS NOT RECOMMENDED                                 | -->
<!-- =================================================================================== -->
<!-- Goat Robot Model, using xacro -->
<robot name="goat_robot">
  <!-- <link name="world">
      </link> 
        
      <joint name="dummy_base" type="fixed">
            <origin xyz="0 0 0" rpy="0 0 0"/>
            <parent link="world"/>
            <child link="${name}"/>
      </joint>  -->

  <gazebo>
    <plugin name="gazebo_ros_control" filename="libgazebo_ros_control.so">
      <robotNamespace>/goat_robot</robotNamespace>
      <robotSimType>gazebo_ros_control/DefaultRobotHWSim</robotSimType>
    </plugin>
  </gazebo>	

  <link name="base_link">
    <visual>
      <origin rpy="0 0 0" xyz="0 0 0"/>
      <geometry>
        <box size="0.25 0.4 0.06"/>
      </geometry>
    </visual>
    <collision>
      <origin rpy="0 0 0" xyz="0 0 0"/>
      <geometry>
        <box size="0.25 0.4 0.06"/>
      </geometry>
    </collision>
    <inertial>
      <mass value="10"/>
      <inertia ixx="0.13633333333333333" ixy="0.0" ixz="0.0" iyy="0.05508333333333334" iyz="0.0" izz="0.1854166666666667"/>
    </inertial>
  </link>
  <gazebo reference="base_link">
    <material>Gazebo/Tertiary</material>
  </gazebo>
  <joint name="LF_base" type="fixed">
    <origin rpy="0 0 1.5707963267948966" xyz="-0.092 0.167 -0.03"/>
    <parent link="base_link"/>
    <child link="LF_base_link"/>
  </joint>
  <link name="LF_base_link">
    <inertial>
      <origin rpy="0 0 0" xyz="0 0 0"/>
      <mass value="0.45"/>
      <inertia ixx="0.001" ixy="0" ixz="0" iyy="0.001" iyz="0" izz="0.001"/>
    </inertial>
    <visual>
      <origin rpy="0 0 0" xyz="0 0 0"/>
      <geometry>
        <mesh filename="package://second_goat_description/meshes/qb_meshes/dae/qb_double_flat_flange_m.dae"/>
      </geometry>
    </visual>
    <visual>
      <origin rpy="1.5707963267948966 3.141592653589793 0" xyz="0 0.033 -0.046"/>
      <geometry>
        <mesh filename="package://second_goat_description/meshes/qb_meshes/dae/qbmove_frame_m.dae"/>
      </geometry>
    </visual>
    <collision>
      <origin rpy="0 0 0" xyz="0 0 0"/>
      <geometry>
        <mesh filename="package://second_goat_description/meshes/qb_meshes/dae/qb_double_flat_flange_m.dae"/>
      </geometry>
    </collision>
    <collision>
      <origin rpy="1.5707963267948966 3.141592653589793 0" xyz="0 0.033 -0.046"/>
      <geometry>
        <mesh filename="package://second_goat_description/meshes/qb_meshes/dae/qbmove_frame_m.dae"/>
      </geometry>
    </collision>
  </link>
  <gazebo>
    <plugin filename="libsea_plugin.so" name="LF_sea_1">
      <joint>LF_hip_joint</joint>
      <namespace>goat_robot</namespace>
      <stiffness>1000</stiffness>
      <pub_eltau>false</pub_eltau>
      <pub_state>true</pub_state>
      <sub_ext_tau>false</sub_ext_tau>
    </plugin>
  </gazebo>
  <joint name="LF_hip_joint" type="revolute">
    <origin rpy="1.5707963267948966 0 0" xyz="0 0 -0.046"/>
    <parent link="LF_base_link"/>
    <child link="LF_femur"/>
    <limit effort="30" lower="-1.5707963267948966" upper="1.5707963267948966" velocity="1.0"/>
    <axis xyz="0 0 1"/>
  </joint>
  <link name="LF_femur">
    <inertial>
      <origin rpy="0 0 0" xyz="0 0 0"/>
      <mass value="0.7"/>
      <inertia ixx="0.001" ixy="0" ixz="0" iyy="0.001" iyz="0" izz="0.001"/>
    </inertial>
    <visual>
      <origin rpy="1.5707963267948966 -1.5707963267948966 0" xyz="0 -0.056 0"/>
      <geometry>
        <mesh filename="package://second_goat_description/meshes/qb_meshes/dae/qb_c_flange_m.dae"/>
      </geometry>
    </visual>
    <collision>
      <origin rpy="1.5707963267948966 -1.5707963267948966 0" xyz="0 -0.056 0"/>
      <geometry>
        <mesh filename="package://second_goat_description/meshes//qb_meshes/dae/qb_c_flange_m.dae"/>
      </geometry>
    </collision>
    <visual>
      <origin rpy="0 0 3.141592653589793" xyz="0 -0.089 -0.033"/>
      <geometry>
        <mesh filename="package://second_goat_description/meshes/qb_meshes/dae/qbmove_frame_m.dae"/>
      </geometry>
    </visual>
    <collision>
      <origin rpy="0 0 3.141592653589793" xyz="0 -0.089 -0.033"/>
      <geometry>
        <mesh filename="package://second_goat_description/meshes/qb_meshes/dae/qbmove_frame_m.dae"/>
      </geometry>
    </collision>
  </link>
  <gazebo>
    <plugin filename="libsea_plugin.so" name="LF_sea_2">
      <joint>LF_knee_joint</joint>
      <namespace>goat_robot</namespace>
      <stiffness>1000</stiffness>
      <pub_eltau>false</pub_eltau>
      <pub_state>true</pub_state>
      <sub_ext_tau>false</sub_ext_tau>
    </plugin>
  </gazebo>
  <joint name="LF_knee_joint" type="revolute">
    <origin rpy="0 0 0" xyz="0 -0.089 0"/>
    <parent link="LF_femur"/>
    <child link="LF_shank"/>
    <limit effort="30" lower="-1.5707963267948966" upper="1.5707963267948966" velocity="1.0"/>
    <axis xyz="0 0 1"/>
  </joint>
  <link name="LF_shank">
    

        #TODO Set the right mass value and inerita too
      
    <inertial>
      <origin rpy="0 0 0" xyz="0 0 0"/>
      <mass value="0.7"/>
      <inertia ixx="0.001" ixy="0" ixz="0" iyy="0.001" iyz="0" izz="0.001"/>
    </inertial>
    <visual>
      <origin rpy="1.5707963267948966 -1.5707963267948966 0" xyz="0 -0.056 0"/>
      <geometry>
        <mesh filename="package://second_goat_description/meshes/qb_meshes/dae/qb_c_flange_m.dae"/>
      </geometry>
    </visual>
    <collision>
      <origin rpy="1.5707963267948966 -1.5707963267948966 0" xyz="0 -0.056 0"/>
      <geometry>
        <mesh filename="package://second_goat_description/meshes//qb_meshes/dae/qb_c_flange_m.dae"/>
      </geometry>
    </collision>
  </link>
  <joint name="RF_base" type="fixed">
    <origin rpy="0 0 1.5707963267948966" xyz="0.092 0.167 -0.03"/>
    <parent link="base_link"/>
    <child link="RF_base_link"/>
  </joint>
  <link name="RF_base_link">
    <inertial>
      <origin rpy="0 0 0" xyz="0 0 0"/>
      <mass value="0.45"/>
      <inertia ixx="0.001" ixy="0" ixz="0" iyy="0.001" iyz="0" izz="0.001"/>
    </inertial>
    <visual>
      <origin rpy="0 0 0" xyz="0 0 0"/>
      <geometry>
        <mesh filename="package://second_goat_description/meshes/qb_meshes/dae/qb_double_flat_flange_m.dae"/>
      </geometry>
    </visual>
    <visual>
      <origin rpy="1.5707963267948966 3.141592653589793 0" xyz="0 0.033 -0.046"/>
      <geometry>
        <mesh filename="package://second_goat_description/meshes/qb_meshes/dae/qbmove_frame_m.dae"/>
      </geometry>
    </visual>
    <collision>
      <origin rpy="0 0 0" xyz="0 0 0"/>
      <geometry>
        <mesh filename="package://second_goat_description/meshes/qb_meshes/dae/qb_double_flat_flange_m.dae"/>
      </geometry>
    </collision>
    <collision>
      <origin rpy="1.5707963267948966 3.141592653589793 0" xyz="0 0.033 -0.046"/>
      <geometry>
        <mesh filename="package://second_goat_description/meshes/qb_meshes/dae/qbmove_frame_m.dae"/>
      </geometry>
    </collision>
  </link>
  <gazebo>
    <plugin filename="libsea_plugin.so" name="RF_sea_1">
      <joint>RF_hip_joint</joint>
      <namespace>goat_robot</namespace>
      <stiffness>1000</stiffness>
      <pub_eltau>false</pub_eltau>
      <pub_state>true</pub_state>
      <sub_ext_tau>false</sub_ext_tau>
    </plugin>
  </gazebo>
  <joint name="RF_hip_joint" type="revolute">
    <origin rpy="1.5707963267948966 0 0" xyz="0 0 -0.046"/>
    <parent link="RF_base_link"/>
    <child link="RF_femur"/>
    <limit effort="30" lower="-1.5707963267948966" upper="1.5707963267948966" velocity="1.0"/>
    <axis xyz="0 0 1"/>
  </joint>
  <link name="RF_femur">
    <inertial>
      <origin rpy="0 0 0" xyz="0 0 0"/>
      <mass value="0.7"/>
      <inertia ixx="0.001" ixy="0" ixz="0" iyy="0.001" iyz="0" izz="0.001"/>
    </inertial>
    <visual>
      <origin rpy="1.5707963267948966 -1.5707963267948966 0" xyz="0 -0.056 0"/>
      <geometry>
        <mesh filename="package://second_goat_description/meshes/qb_meshes/dae/qb_c_flange_m.dae"/>
      </geometry>
    </visual>
    <collision>
      <origin rpy="1.5707963267948966 -1.5707963267948966 0" xyz="0 -0.056 0"/>
      <geometry>
        <mesh filename="package://second_goat_description/meshes//qb_meshes/dae/qb_c_flange_m.dae"/>
      </geometry>
    </collision>
    <visual>
      <origin rpy="0 0 3.141592653589793" xyz="0 -0.089 -0.033"/>
      <geometry>
        <mesh filename="package://second_goat_description/meshes/qb_meshes/dae/qbmove_frame_m.dae"/>
      </geometry>
    </visual>
    <collision>
      <origin rpy="0 0 3.141592653589793" xyz="0 -0.089 -0.033"/>
      <geometry>
        <mesh filename="package://second_goat_description/meshes/qb_meshes/dae/qbmove_frame_m.dae"/>
      </geometry>
    </collision>
  </link>
  <gazebo>
    <plugin filename="libsea_plugin.so" name="RF_sea_2">
      <joint>RF_knee_joint</joint>
      <namespace>goat_robot</namespace>
      <stiffness>1000</stiffness>
      <pub_eltau>false</pub_eltau>
      <pub_state>true</pub_state>
      <sub_ext_tau>false</sub_ext_tau>
    </plugin>
  </gazebo>
  <joint name="RF_knee_joint" type="revolute">
    <origin rpy="0 0 0" xyz="0 -0.089 0"/>
    <parent link="RF_femur"/>
    <child link="RF_shank"/>
    <limit effort="30" lower="-1.5707963267948966" upper="1.5707963267948966" velocity="1.0"/>
    <axis xyz="0 0 1"/>
  </joint>
  <link name="RF_shank">
    

        #TODO Set the right mass value and inerita too
      
    <inertial>
      <origin rpy="0 0 0" xyz="0 0 0"/>
      <mass value="0.7"/>
      <inertia ixx="0.001" ixy="0" ixz="0" iyy="0.001" iyz="0" izz="0.001"/>
    </inertial>
    <visual>
      <origin rpy="1.5707963267948966 -1.5707963267948966 0" xyz="0 -0.056 0"/>
      <geometry>
        <mesh filename="package://second_goat_description/meshes/qb_meshes/dae/qb_c_flange_m.dae"/>
      </geometry>
    </visual>
    <collision>
      <origin rpy="1.5707963267948966 -1.5707963267948966 0" xyz="0 -0.056 0"/>
      <geometry>
        <mesh filename="package://second_goat_description/meshes//qb_meshes/dae/qb_c_flange_m.dae"/>
      </geometry>
    </collision>
  </link>
  <joint name="LH_base" type="fixed">
    <origin rpy="0 0 1.5707963267948966" xyz="-0.092 -0.167 -0.03"/>
    <parent link="base_link"/>
    <child link="LH_base_link"/>
  </joint>
  <link name="LH_base_link">
    <inertial>
      <origin rpy="0 0 0" xyz="0 0 0"/>
      <mass value="0.45"/>
      <inertia ixx="0.001" ixy="0" ixz="0" iyy="0.001" iyz="0" izz="0.001"/>
    </inertial>
    <visual>
      <origin rpy="0 0 0" xyz="0 0 0"/>
      <geometry>
        <mesh filename="package://second_goat_description/meshes/qb_meshes/dae/qb_double_flat_flange_m.dae"/>
      </geometry>
    </visual>
    <visual>
      <origin rpy="1.5707963267948966 3.141592653589793 0" xyz="0 0.033 -0.046"/>
      <geometry>
        <mesh filename="package://second_goat_description/meshes/qb_meshes/dae/qbmove_frame_m.dae"/>
      </geometry>
    </visual>
    <collision>
      <origin rpy="0 0 0" xyz="0 0 0"/>
      <geometry>
        <mesh filename="package://second_goat_description/meshes/qb_meshes/dae/qb_double_flat_flange_m.dae"/>
      </geometry>
    </collision>
    <collision>
      <origin rpy="1.5707963267948966 3.141592653589793 0" xyz="0 0.033 -0.046"/>
      <geometry>
        <mesh filename="package://second_goat_description/meshes/qb_meshes/dae/qbmove_frame_m.dae"/>
      </geometry>
    </collision>
  </link>
  <gazebo>
    <plugin filename="libsea_plugin.so" name="LH_sea_1">
      <joint>LH_hip_joint</joint>
      <namespace>goat_robot</namespace>
      <stiffness>1000</stiffness>
      <pub_eltau>false</pub_eltau>
      <pub_state>true</pub_state>
      <sub_ext_tau>false</sub_ext_tau>
    </plugin>
  </gazebo>
  <joint name="LH_hip_joint" type="revolute">
    <origin rpy="1.5707963267948966 0 0" xyz="0 0 -0.046"/>
    <parent link="LH_base_link"/>
    <child link="LH_femur"/>
    <limit effort="30" lower="-1.5707963267948966" upper="1.5707963267948966" velocity="1.0"/>
    <axis xyz="0 0 1"/>
  </joint>
  <link name="LH_femur">
    <inertial>
      <origin rpy="0 0 0" xyz="0 0 0"/>
      <mass value="0.7"/>
      <inertia ixx="0.001" ixy="0" ixz="0" iyy="0.001" iyz="0" izz="0.001"/>
    </inertial>
    <visual>
      <origin rpy="1.5707963267948966 -1.5707963267948966 0" xyz="0 -0.056 0"/>
      <geometry>
        <mesh filename="package://second_goat_description/meshes/qb_meshes/dae/qb_c_flange_m.dae"/>
      </geometry>
    </visual>
    <collision>
      <origin rpy="1.5707963267948966 -1.5707963267948966 0" xyz="0 -0.056 0"/>
      <geometry>
        <mesh filename="package://second_goat_description/meshes//qb_meshes/dae/qb_c_flange_m.dae"/>
      </geometry>
    </collision>
    <visual>
      <origin rpy="0 0 3.141592653589793" xyz="0 -0.089 -0.033"/>
      <geometry>
        <mesh filename="package://second_goat_description/meshes/qb_meshes/dae/qbmove_frame_m.dae"/>
      </geometry>
    </visual>
    <collision>
      <origin rpy="0 0 3.141592653589793" xyz="0 -0.089 -0.033"/>
      <geometry>
        <mesh filename="package://second_goat_description/meshes/qb_meshes/dae/qbmove_frame_m.dae"/>
      </geometry>
    </collision>
  </link>
  <gazebo>
    <plugin filename="libsea_plugin.so" name="LH_sea_2">
      <joint>LH_knee_joint</joint>
      <namespace>goat_robot</namespace>
      <stiffness>1000</stiffness>
      <pub_eltau>false</pub_eltau>
      <pub_state>true</pub_state>
      <sub_ext_tau>false</sub_ext_tau>
    </plugin>
  </gazebo>
  <joint name="LH_knee_joint" type="revolute">
    <origin rpy="0 0 0" xyz="0 -0.089 0"/>
    <parent link="LH_femur"/>
    <child link="LH_shank"/>
    <limit effort="30" lower="-1.5707963267948966" upper="1.5707963267948966" velocity="1.0"/>
    <axis xyz="0 0 1"/>
  </joint>
  <link name="LH_shank">
    

        #TODO Set the right mass value and inerita too
      
    <inertial>
      <origin rpy="0 0 0" xyz="0 0 0"/>
      <mass value="0.7"/>
      <inertia ixx="0.001" ixy="0" ixz="0" iyy="0.001" iyz="0" izz="0.001"/>
    </inertial>
    <visual>
      <origin rpy="1.5707963267948966 -1.5707963267948966 0" xyz="0 -0.056 0"/>
      <geometry>
        <mesh filename="package://second_goat_description/meshes/qb_meshes/dae/qb_c_flange_m.dae"/>
      </geometry>
    </visual>
    <collision>
      <origin rpy="1.5707963267948966 -1.5707963267948966 0" xyz="0 -0.056 0"/>
      <geometry>
        <mesh filename="package://second_goat_description/meshes//qb_meshes/dae/qb_c_flange_m.dae"/>
      </geometry>
    </collision>
  </link>
  <joint name="RH_base" type="fixed">
    <origin rpy="0 0 1.5707963267948966" xyz="0.092 -0.167 -0.03"/>
    <parent link="base_link"/>
    <child link="RH_base_link"/>
  </joint>
  <link name="RH_base_link">
    <inertial>
      <origin rpy="0 0 0" xyz="0 0 0"/>
      <mass value="0.45"/>
      <inertia ixx="0.001" ixy="0" ixz="0" iyy="0.001" iyz="0" izz="0.001"/>
    </inertial>
    <visual>
      <origin rpy="0 0 0" xyz="0 0 0"/>
      <geometry>
        <mesh filename="package://second_goat_description/meshes/qb_meshes/dae/qb_double_flat_flange_m.dae"/>
      </geometry>
    </visual>
    <visual>
      <origin rpy="1.5707963267948966 3.141592653589793 0" xyz="0 0.033 -0.046"/>
      <geometry>
        <mesh filename="package://second_goat_description/meshes/qb_meshes/dae/qbmove_frame_m.dae"/>
      </geometry>
    </visual>
    <collision>
      <origin rpy="0 0 0" xyz="0 0 0"/>
      <geometry>
        <mesh filename="package://second_goat_description/meshes/qb_meshes/dae/qb_double_flat_flange_m.dae"/>
      </geometry>
    </collision>
    <collision>
      <origin rpy="1.5707963267948966 3.141592653589793 0" xyz="0 0.033 -0.046"/>
      <geometry>
        <mesh filename="package://second_goat_description/meshes/qb_meshes/dae/qbmove_frame_m.dae"/>
      </geometry>
    </collision>
  </link>
  <gazebo>
    <plugin filename="libsea_plugin.so" name="RH_sea_1">
      <joint>RH_hip_joint</joint>
      <namespace>goat_robot</namespace>
      <stiffness>1000</stiffness>
      <pub_eltau>false</pub_eltau>
      <pub_state>true</pub_state>
      <sub_ext_tau>false</sub_ext_tau>
    </plugin>
  </gazebo>
  <joint name="RH_hip_joint" type="revolute">
    <origin rpy="1.5707963267948966 0 0" xyz="0 0 -0.046"/>
    <parent link="RH_base_link"/>
    <child link="RH_femur"/>
    <limit effort="30" lower="-1.5707963267948966" upper="1.5707963267948966" velocity="1.0"/>
    <axis xyz="0 0 1"/>
  </joint>
  <link name="RH_femur">
    <inertial>
      <origin rpy="0 0 0" xyz="0 0 0"/>
      <mass value="0.7"/>
      <inertia ixx="0.001" ixy="0" ixz="0" iyy="0.001" iyz="0" izz="0.001"/>
    </inertial>
    <visual>
      <origin rpy="1.5707963267948966 -1.5707963267948966 0" xyz="0 -0.056 0"/>
      <geometry>
        <mesh filename="package://second_goat_description/meshes/qb_meshes/dae/qb_c_flange_m.dae"/>
      </geometry>
    </visual>
    <collision>
      <origin rpy="1.5707963267948966 -1.5707963267948966 0" xyz="0 -0.056 0"/>
      <geometry>
        <mesh filename="package://second_goat_description/meshes//qb_meshes/dae/qb_c_flange_m.dae"/>
      </geometry>
    </collision>
    <visual>
      <origin rpy="0 0 3.141592653589793" xyz="0 -0.089 -0.033"/>
      <geometry>
        <mesh filename="package://second_goat_description/meshes/qb_meshes/dae/qbmove_frame_m.dae"/>
      </geometry>
    </visual>
    <collision>
      <origin rpy="0 0 3.141592653589793" xyz="0 -0.089 -0.033"/>
      <geometry>
        <mesh filename="package://second_goat_description/meshes/qb_meshes/dae/qbmove_frame_m.dae"/>
      </geometry>
    </collision>
  </link>
  <gazebo>
    <plugin filename="libsea_plugin.so" name="RH_sea_2">
      <joint>RH_knee_joint</joint>
      <namespace>goat_robot</namespace>
      <stiffness>1000</stiffness>
      <pub_eltau>false</pub_eltau>
      <pub_state>true</pub_state>
      <sub_ext_tau>false</sub_ext_tau>
    </plugin>
  </gazebo>
  <joint name="RH_knee_joint" type="revolute">
    <origin rpy="0 0 0" xyz="0 -0.089 0"/>
    <parent link="RH_femur"/>
    <child link="RH_shank"/>
    <limit effort="30" lower="-1.5707963267948966" upper="1.5707963267948966" velocity="1.0"/>
    <axis xyz="0 0 1"/>
  </joint>
  <link name="RH_shank">
    

        #TODO Set the right mass value and inerita too
      
    <inertial>
      <origin rpy="0 0 0" xyz="0 0 0"/>
      <mass value="0.7"/>
      <inertia ixx="0.001" ixy="0" ixz="0" iyy="0.001" iyz="0" izz="0.001"/>
    </inertial>
    <visual>
      <origin rpy="1.5707963267948966 -1.5707963267948966 0" xyz="0 -0.056 0"/>
      <geometry>
        <mesh filename="package://second_goat_description/meshes/qb_meshes/dae/qb_c_flange_m.dae"/>
      </geometry>
    </visual>
    <collision>
      <origin rpy="1.5707963267948966 -1.5707963267948966 0" xyz="0 -0.056 0"/>
      <geometry>
        <mesh filename="package://second_goat_description/meshes//qb_meshes/dae/qb_c_flange_m.dae"/>
      </geometry>
    </collision>
  </link>
  <!-- Uncomment this part if you don't want apply the goat hoof -->
  <!-- <link name="world">
  </link>  -->
  <joint name="shank_to_hoof_LF" type="fixed">
    <origin rpy="-1.5707963267948966 0 0" xyz="0 -0.076 0"/>
    <parent link="LF_shank"/>
    <child link="metacarpus_LF"/>
  </joint>
  <link name="metacarpus_LF">
    <visual>
      <origin rpy="0 0 0" xyz="0 0 0"/>
      <geometry>
        <cylinder length="0.04" radius="0.03"/>
      </geometry>
    </visual>
    <collision>
      <origin rpy="0 0 0" xyz="0 0 0"/>
      <geometry>
        <cylinder length="0.04" radius="0.03"/>
      </geometry>
    </collision>
    <inertial>
      <mass value="0.5"/>
      <origin rpy="0 0 0" xyz="0 0 0"/>
      <inertia ixx="0.00012916666666666667" ixy="0.0" ixz="0.0" iyy="0.00012916666666666667" iyz="0.0" izz="0.000225"/>
    </inertial>
  </link>
  <gazebo reference="metacarpus_LF">
    <material>Gazebo/Tertiary</material>
  </gazebo>
  <!-- <link name="world">
  </link>  -->
  <joint name="shank_to_hoof_RF" type="fixed">
    <origin rpy="-1.5707963267948966 0 0" xyz="0 -0.076 0"/>
    <parent link="RF_shank"/>
    <child link="metacarpus_RF"/>
  </joint>
  <link name="metacarpus_RF">
    <visual>
      <origin rpy="0 0 0" xyz="0 0 0"/>
      <geometry>
        <cylinder length="0.04" radius="0.03"/>
      </geometry>
    </visual>
    <collision>
      <origin rpy="0 0 0" xyz="0 0 0"/>
      <geometry>
        <cylinder length="0.04" radius="0.03"/>
      </geometry>
    </collision>
    <inertial>
      <mass value="0.5"/>
      <origin rpy="0 0 0" xyz="0 0 0"/>
      <inertia ixx="0.00012916666666666667" ixy="0.0" ixz="0.0" iyy="0.00012916666666666667" iyz="0.0" izz="0.000225"/>
    </inertial>
  </link>
  <gazebo reference="metacarpus_RF">
    <material>Gazebo/Tertiary</material>
  </gazebo>
  <!-- <link name="world">
  </link>  -->
  <joint name="shank_to_hoof_LH" type="fixed">
    <origin rpy="-1.5707963267948966 0 0" xyz="0 -0.076 0"/>
    <parent link="LH_shank"/>
    <child link="metacarpus_LH"/>
  </joint>
  <link name="metacarpus_LH">
    <visual>
      <origin rpy="0 0 0" xyz="0 0 0"/>
      <geometry>
        <cylinder length="0.04" radius="0.03"/>
      </geometry>
    </visual>
    <collision>
      <origin rpy="0 0 0" xyz="0 0 0"/>
      <geometry>
        <cylinder length="0.04" radius="0.03"/>
      </geometry>
    </collision>
    <inertial>
      <mass value="0.5"/>
      <origin rpy="0 0 0" xyz="0 0 0"/>
      <inertia ixx="0.00012916666666666667" ixy="0.0" ixz="0.0" iyy="0.00012916666666666667" iyz="0.0" izz="0.000225"/>
    </inertial>
  </link>
  <gazebo reference="metacarpus_LH">
    <material>Gazebo/Tertiary</material>
  </gazebo>
  <!-- <link name="world">
  </link>  -->
  <joint name="shank_to_hoof_RH" type="fixed">
    <origin rpy="-1.5707963267948966 0 0" xyz="0 -0.076 0"/>
    <parent link="RH_shank"/>
    <child link="metacarpus_RH"/>
  </joint>
  <link name="metacarpus_RH">
    <visual>
      <origin rpy="0 0 0" xyz="0 0 0"/>
      <geometry>
        <cylinder length="0.04" radius="0.03"/>
      </geometry>
    </visual>
    <collision>
      <origin rpy="0 0 0" xyz="0 0 0"/>
      <geometry>
        <cylinder length="0.04" radius="0.03"/>
      </geometry>
    </collision>
    <inertial>
      <mass value="0.5"/>
      <origin rpy="0 0 0" xyz="0 0 0"/>
      <inertia ixx="0.00012916666666666667" ixy="0.0" ixz="0.0" iyy="0.00012916666666666667" iyz="0.0" izz="0.000225"/>
    </inertial>
  </link>
  <gazebo reference="metacarpus_RH">
    <material>Gazebo/Tertiary</material>
  </gazebo>
  <joint name="joint_L_fetlock_RF" type="revolute">
    <parent link="metacarpus_RF"/>
    <child link="RF_L_declaw"/>
    <origin rpy="0 1.5707963267948966 0" xyz="0 -0.015 0"/>
    <axis xyz="0 0 1"/>
    <limit effort="30" lower="-0.04" upper="0.04" velocity="1.0"/>
    <dynamics damping="0.1" friction="0"/>
  </joint>
  <gazebo>
    <plugin filename="libsea_plugin.so" name="L_sea_j3">
      <joint>joint_L_fetlock_RF</joint>
      <namespace>goat_hoof</namespace>
      <stiffness>10</stiffness>
      <pub_eltau>true</pub_eltau>
      <pub_state>true</pub_state>
      <sub_ext_tau>true</sub_ext_tau>
    </plugin>
  </gazebo>
  <link name="RF_L_declaw">
    <visual>
      <origin rpy="0 0 0" xyz="0 0 0"/>
      <geometry>
        <cylinder length="0.02" radius="0.008"/>
      </geometry>
    </visual>
    <collision>
      <origin rpy="0 0 0" xyz="0 0 0"/>
      <geometry>
        <cylinder length="0.02" radius="0.008"/>
      </geometry>
    </collision>
    <inertial>
      <mass value="0.1"/>
      <origin rpy="0 0 0" xyz="0 0 0"/>
      <inertia ixx="4.933333333333334e-06" ixy="0.0" ixz="0.0" iyy="4.933333333333334e-06" iyz="0.0" izz="3.2e-06"/>
    </inertial>
  </link>
  <joint name="joint_L_pastern_RF" type="prismatic">
    <parent link="RF_L_declaw"/>
    <child link="RF_L_phalange"/>
    <origin rpy="0 -1.5707963267948966 0" xyz="0 0 0"/>
    <axis xyz="0 0 1"/>
    <limit effort="30" lower="-0.02" upper="0.02" velocity="1.0"/>
    <dynamics damping="50.0" friction="0"/>
  </joint>
  <gazebo>
    <plugin filename="libsea_plugin.so" name="L_sea_j4">
      <joint>joint_L_pastern_RF</joint>
      <namespace>goat_robot</namespace>
      <stiffness>10000</stiffness>
      <pub_eltau>true</pub_eltau>
      <pub_state>true</pub_state>
      <sub_ext_tau>true</sub_ext_tau>
    </plugin>
  </gazebo>
  <link name="RF_L_phalange">
    <visual>
      <origin rpy="0 0 0" xyz="0 0 -0.03"/>
      <geometry>
        <cylinder length="0.06" radius="0.008"/>
      </geometry>
    </visual>
    <collision>
      <origin rpy="0 0 0" xyz="0 0 -0.03"/>
      <geometry>
        <cylinder length="0.06" radius="0.008"/>
      </geometry>
    </collision>
    <inertial>
      <mass value="0.2"/>
      <origin rpy="0 0 0" xyz="0 0 -0.03"/>
      <inertia ixx="6.32e-05" ixy="0.0" ixz="0.0" iyy="6.32e-05" iyz="0.0" izz="6.4e-06"/>
    </inertial>
  </link>
  <gazebo reference="RF_L_phalange">
    <material>Gazebo/Tertiary</material>
  </gazebo>
  <joint name="joint_L_coffin_RF" type="revolute">
    <parent link="RF_L_phalange"/>
    <child link="RF_L_claw"/>
    <origin rpy="0 0 0" xyz="0 0 -0.06"/>
    <axis xyz="0 0 1"/>
    <limit effort="30" lower="-0.5" upper="0.25" velocity="1"/>
    <dynamics damping="0.07" friction="0"/>
  </joint>
  <gazebo reference="joint_L_coffin_RF">
    <implicitSpringDamper>True</implicitSpringDamper>
  </gazebo>
  <gazebo>
    <plugin filename="libsea_plugin.so" name="L_sea_j5">
      <joint>joint_L_coffin_RF</joint>
      <namespace>goat_robot</namespace>
      <stiffness>0.5</stiffness>
      <pub_eltau>true</pub_eltau>
      <pub_state>true</pub_state>
      <sub_ext_tau>true</sub_ext_tau>
    </plugin>
  </gazebo>
  <!-- <xacro:if value="${side == 'R'}">
 <xacro:property name="claw_origin_xyz" value="0 ${phalange_radius/2} 0"/>
 <xacro:property name="mesh_claw" value="package://second_goat_description/meshes/stl/MirrorClaw.stl" />
</xacro:if> 

<xacro:if value="${side == 'L'}">
 <xacro:property name="claw_origin_xyz" value="0 ${-phalange_radius/2} 0"/>
 <xacro:property name="mesh_claw" value="package://second_goat_description/meshes/stl/Claw.stl" />
</xacro:if>  -->
  <link name="RF_L_claw">
    <visual>
      <origin rpy="-1.5707963267948966 0 1.5707963267948966" xyz="0.05 -0.020 0.005"/>
      <geometry>
        <mesh filename="package://second_goat_description/meshes/Claw.stl" scale="0.0012 0.0012 0.0012"/>
      </geometry>
    </visual>
    <collision>
      <origin rpy="-1.5707963267948966 0 1.5707963267948966" xyz="0.05 -0.020 0.005"/>
      <geometry>
        <mesh filename="package://second_goat_description/meshes/Claw.stl" scale="0.0012 0.0012 0.0012"/>
      </geometry>
    </collision>
    <inertial>
      <mass value="0.05"/>
      <origin rpy="0 0 0" xyz="0.01 -0.004 0"/>
      <inertia ixx="3.759375e-06" ixy="0.0" ixz="0.0" iyy="1.5009375000000002e-05" iyz="0.0" izz="1.875e-05"/>
    </inertial>
  </link>
  <gazebo reference="RF_L_claw">
    <material>Gazebo/Tertiary</material>
  </gazebo>
  <joint name="joint_R_fetlock_RF" type="revolute">
    <parent link="metacarpus_RF"/>
    <child link="RF_R_declaw"/>
    <origin rpy="0 1.5707963267948966 0" xyz="0 0.015 0"/>
    <axis xyz="0 0 1"/>
    <limit effort="30" lower="-0.04" upper="0.04" velocity="1.0"/>
    <dynamics damping="0.1" friction="0"/>
  </joint>
  <gazebo>
    <plugin filename="libsea_plugin.so" name="R_sea_j3">
      <joint>joint_R_fetlock_RF</joint>
      <namespace>goat_hoof</namespace>
      <stiffness>10</stiffness>
      <pub_eltau>true</pub_eltau>
      <pub_state>true</pub_state>
      <sub_ext_tau>true</sub_ext_tau>
    </plugin>
  </gazebo>
  <link name="RF_R_declaw">
    <visual>
      <origin rpy="0 0 0" xyz="0 0 0"/>
      <geometry>
        <cylinder length="0.02" radius="0.008"/>
      </geometry>
    </visual>
    <collision>
      <origin rpy="0 0 0" xyz="0 0 0"/>
      <geometry>
        <cylinder length="0.02" radius="0.008"/>
      </geometry>
    </collision>
    <inertial>
      <mass value="0.1"/>
      <origin rpy="0 0 0" xyz="0 0 0"/>
      <inertia ixx="4.933333333333334e-06" ixy="0.0" ixz="0.0" iyy="4.933333333333334e-06" iyz="0.0" izz="3.2e-06"/>
    </inertial>
  </link>
  <joint name="joint_R_pastern_RF" type="prismatic">
    <parent link="RF_R_declaw"/>
    <child link="RF_R_phalange"/>
    <origin rpy="0 -1.5707963267948966 0" xyz="0 0 0"/>
    <axis xyz="0 0 1"/>
    <limit effort="30" lower="-0.02" upper="0.02" velocity="1.0"/>
    <dynamics damping="50.0" friction="0"/>
  </joint>
  <gazebo>
    <plugin filename="libsea_plugin.so" name="R_sea_j4">
      <joint>joint_R_pastern_RF</joint>
      <namespace>goat_robot</namespace>
      <stiffness>10000</stiffness>
      <pub_eltau>true</pub_eltau>
      <pub_state>true</pub_state>
      <sub_ext_tau>true</sub_ext_tau>
    </plugin>
  </gazebo>
  <link name="RF_R_phalange">
    <visual>
      <origin rpy="0 0 0" xyz="0 0 -0.03"/>
      <geometry>
        <cylinder length="0.06" radius="0.008"/>
      </geometry>
    </visual>
    <collision>
      <origin rpy="0 0 0" xyz="0 0 -0.03"/>
      <geometry>
        <cylinder length="0.06" radius="0.008"/>
      </geometry>
    </collision>
    <inertial>
      <mass value="0.2"/>
      <origin rpy="0 0 0" xyz="0 0 -0.03"/>
      <inertia ixx="6.32e-05" ixy="0.0" ixz="0.0" iyy="6.32e-05" iyz="0.0" izz="6.4e-06"/>
    </inertial>
  </link>
  <gazebo reference="RF_R_phalange">
    <material>Gazebo/Tertiary</material>
  </gazebo>
  <joint name="joint_R_coffin_RF" type="revolute">
    <parent link="RF_R_phalange"/>
    <child link="RF_R_claw"/>
    <origin rpy="0 0 0" xyz="0 0 -0.06"/>
    <axis xyz="0 0 1"/>
    <limit effort="30" lower="-0.25" upper="0.5" velocity="1"/>
    <dynamics damping="0.07" friction="0"/>
  </joint>
  <gazebo reference="joint_R_coffin_RF">
    <implicitSpringDamper>True</implicitSpringDamper>
  </gazebo>
  <gazebo>
    <plugin filename="libsea_plugin.so" name="R_sea_j5">
      <joint>joint_R_coffin_RF</joint>
      <namespace>goat_robot</namespace>
      <stiffness>0.5</stiffness>
      <pub_eltau>true</pub_eltau>
      <pub_state>true</pub_state>
      <sub_ext_tau>true</sub_ext_tau>
    </plugin>
  </gazebo>
  <!-- <xacro:if value="${side == 'R'}">
 <xacro:property name="claw_origin_xyz" value="0 ${phalange_radius/2} 0"/>
 <xacro:property name="mesh_claw" value="package://second_goat_description/meshes/stl/MirrorClaw.stl" />
</xacro:if> 

<xacro:if value="${side == 'L'}">
 <xacro:property name="claw_origin_xyz" value="0 ${-phalange_radius/2} 0"/>
 <xacro:property name="mesh_claw" value="package://second_goat_description/meshes/stl/Claw.stl" />
</xacro:if>  -->
  <link name="RF_R_claw">
    <visual>
      <origin rpy="-1.5707963267948966 0 1.5707963267948966" xyz="0.05 -0.05 0.005"/>
      <geometry>
        <mesh filename="package://second_goat_description/meshes/MirrorClaw.stl" scale="0.0012 0.0012 0.0012"/>
      </geometry>
    </visual>
    <collision>
      <origin rpy="-1.5707963267948966 0 1.5707963267948966" xyz="0.05 -0.05 0.005"/>
      <geometry>
        <mesh filename="package://second_goat_description/meshes/MirrorClaw.stl" scale="0.0012 0.0012 0.0012"/>
      </geometry>
    </collision>
    <inertial>
      <mass value="0.05"/>
      <origin rpy="0 0 0" xyz="0.01 0.004 0"/>
      <inertia ixx="3.759375e-06" ixy="0.0" ixz="0.0" iyy="1.5009375000000002e-05" iyz="0.0" izz="1.875e-05"/>
    </inertial>
  </link>
  <gazebo reference="RF_R_claw">
    <material>Gazebo/Tertiary</material>
  </gazebo>
  <joint name="joint_L_fetlock_LF" type="revolute">
    <parent link="metacarpus_LF"/>
    <child link="LF_L_declaw"/>
    <origin rpy="0 1.5707963267948966 0" xyz="0 -0.015 0"/>
    <axis xyz="0 0 1"/>
    <limit effort="30" lower="-0.04" upper="0.04" velocity="1.0"/>
    <dynamics damping="0.1" friction="0"/>
  </joint>
  <gazebo>
    <plugin filename="libsea_plugin.so" name="L_sea_j3">
      <joint>joint_L_fetlock_LF</joint>
      <namespace>goat_hoof</namespace>
      <stiffness>10</stiffness>
      <pub_eltau>true</pub_eltau>
      <pub_state>true</pub_state>
      <sub_ext_tau>true</sub_ext_tau>
    </plugin>
  </gazebo>
  <link name="LF_L_declaw">
    <visual>
      <origin rpy="0 0 0" xyz="0 0 0"/>
      <geometry>
        <cylinder length="0.02" radius="0.008"/>
      </geometry>
    </visual>
    <collision>
      <origin rpy="0 0 0" xyz="0 0 0"/>
      <geometry>
        <cylinder length="0.02" radius="0.008"/>
      </geometry>
    </collision>
    <inertial>
      <mass value="0.1"/>
      <origin rpy="0 0 0" xyz="0 0 0"/>
      <inertia ixx="4.933333333333334e-06" ixy="0.0" ixz="0.0" iyy="4.933333333333334e-06" iyz="0.0" izz="3.2e-06"/>
    </inertial>
  </link>
  <joint name="joint_L_pastern_LF" type="prismatic">
    <parent link="LF_L_declaw"/>
    <child link="LF_L_phalange"/>
    <origin rpy="0 -1.5707963267948966 0" xyz="0 0 0"/>
    <axis xyz="0 0 1"/>
    <limit effort="30" lower="-0.02" upper="0.02" velocity="1.0"/>
    <dynamics damping="50.0" friction="0"/>
  </joint>
  <gazebo>
    <plugin filename="libsea_plugin.so" name="L_sea_j4">
      <joint>joint_L_pastern_LF</joint>
      <namespace>goat_robot</namespace>
      <stiffness>10000</stiffness>
      <pub_eltau>true</pub_eltau>
      <pub_state>true</pub_state>
      <sub_ext_tau>true</sub_ext_tau>
    </plugin>
  </gazebo>
  <link name="LF_L_phalange">
    <visual>
      <origin rpy="0 0 0" xyz="0 0 -0.03"/>
      <geometry>
        <cylinder length="0.06" radius="0.008"/>
      </geometry>
    </visual>
    <collision>
      <origin rpy="0 0 0" xyz="0 0 -0.03"/>
      <geometry>
        <cylinder length="0.06" radius="0.008"/>
      </geometry>
    </collision>
    <inertial>
      <mass value="0.2"/>
      <origin rpy="0 0 0" xyz="0 0 -0.03"/>
      <inertia ixx="6.32e-05" ixy="0.0" ixz="0.0" iyy="6.32e-05" iyz="0.0" izz="6.4e-06"/>
    </inertial>
  </link>
  <gazebo reference="LF_L_phalange">
    <material>Gazebo/Tertiary</material>
  </gazebo>
  <joint name="joint_L_coffin_LF" type="revolute">
    <parent link="LF_L_phalange"/>
    <child link="LF_L_claw"/>
    <origin rpy="0 0 0" xyz="0 0 -0.06"/>
    <axis xyz="0 0 1"/>
    <limit effort="30" lower="-0.5" upper="0.25" velocity="1"/>
    <dynamics damping="0.07" friction="0"/>
  </joint>
  <gazebo reference="joint_L_coffin_LF">
    <implicitSpringDamper>True</implicitSpringDamper>
  </gazebo>
  <gazebo>
    <plugin filename="libsea_plugin.so" name="L_sea_j5">
      <joint>joint_L_coffin_LF</joint>
      <namespace>goat_robot</namespace>
      <stiffness>0.5</stiffness>
      <pub_eltau>true</pub_eltau>
      <pub_state>true</pub_state>
      <sub_ext_tau>true</sub_ext_tau>
    </plugin>
  </gazebo>
  <!-- <xacro:if value="${side == 'R'}">
 <xacro:property name="claw_origin_xyz" value="0 ${phalange_radius/2} 0"/>
 <xacro:property name="mesh_claw" value="package://second_goat_description/meshes/stl/MirrorClaw.stl" />
</xacro:if> 

<xacro:if value="${side == 'L'}">
 <xacro:property name="claw_origin_xyz" value="0 ${-phalange_radius/2} 0"/>
 <xacro:property name="mesh_claw" value="package://second_goat_description/meshes/stl/Claw.stl" />
</xacro:if>  -->
  <link name="LF_L_claw">
    <visual>
      <origin rpy="-1.5707963267948966 0 1.5707963267948966" xyz="0.05 -0.020 0.005"/>
      <geometry>
        <mesh filename="package://second_goat_description/meshes/Claw.stl" scale="0.0012 0.0012 0.0012"/>
      </geometry>
    </visual>
    <collision>
      <origin rpy="-1.5707963267948966 0 1.5707963267948966" xyz="0.05 -0.020 0.005"/>
      <geometry>
        <mesh filename="package://second_goat_description/meshes/Claw.stl" scale="0.0012 0.0012 0.0012"/>
      </geometry>
    </collision>
    <inertial>
      <mass value="0.05"/>
      <origin rpy="0 0 0" xyz="0.01 -0.004 0"/>
      <inertia ixx="3.759375e-06" ixy="0.0" ixz="0.0" iyy="1.5009375000000002e-05" iyz="0.0" izz="1.875e-05"/>
    </inertial>
  </link>
  <gazebo reference="LF_L_claw">
    <material>Gazebo/Tertiary</material>
  </gazebo>
  <joint name="joint_R_fetlock_LF" type="revolute">
    <parent link="metacarpus_LF"/>
    <child link="LF_R_declaw"/>
    <origin rpy="0 1.5707963267948966 0" xyz="0 0.015 0"/>
    <axis xyz="0 0 1"/>
    <limit effort="30" lower="-0.04" upper="0.04" velocity="1.0"/>
    <dynamics damping="0.1" friction="0"/>
  </joint>
  <gazebo>
    <plugin filename="libsea_plugin.so" name="R_sea_j3">
      <joint>joint_R_fetlock_LF</joint>
      <namespace>goat_hoof</namespace>
      <stiffness>10</stiffness>
      <pub_eltau>true</pub_eltau>
      <pub_state>true</pub_state>
      <sub_ext_tau>true</sub_ext_tau>
    </plugin>
  </gazebo>
  <link name="LF_R_declaw">
    <visual>
      <origin rpy="0 0 0" xyz="0 0 0"/>
      <geometry>
        <cylinder length="0.02" radius="0.008"/>
      </geometry>
    </visual>
    <collision>
      <origin rpy="0 0 0" xyz="0 0 0"/>
      <geometry>
        <cylinder length="0.02" radius="0.008"/>
      </geometry>
    </collision>
    <inertial>
      <mass value="0.1"/>
      <origin rpy="0 0 0" xyz="0 0 0"/>
      <inertia ixx="4.933333333333334e-06" ixy="0.0" ixz="0.0" iyy="4.933333333333334e-06" iyz="0.0" izz="3.2e-06"/>
    </inertial>
  </link>
  <joint name="joint_R_pastern_LF" type="prismatic">
    <parent link="LF_R_declaw"/>
    <child link="LF_R_phalange"/>
    <origin rpy="0 -1.5707963267948966 0" xyz="0 0 0"/>
    <axis xyz="0 0 1"/>
    <limit effort="30" lower="-0.02" upper="0.02" velocity="1.0"/>
    <dynamics damping="50.0" friction="0"/>
  </joint>
  <gazebo>
    <plugin filename="libsea_plugin.so" name="R_sea_j4">
      <joint>joint_R_pastern_LF</joint>
      <namespace>goat_robot</namespace>
      <stiffness>10000</stiffness>
      <pub_eltau>true</pub_eltau>
      <pub_state>true</pub_state>
      <sub_ext_tau>true</sub_ext_tau>
    </plugin>
  </gazebo>
  <link name="LF_R_phalange">
    <visual>
      <origin rpy="0 0 0" xyz="0 0 -0.03"/>
      <geometry>
        <cylinder length="0.06" radius="0.008"/>
      </geometry>
    </visual>
    <collision>
      <origin rpy="0 0 0" xyz="0 0 -0.03"/>
      <geometry>
        <cylinder length="0.06" radius="0.008"/>
      </geometry>
    </collision>
    <inertial>
      <mass value="0.2"/>
      <origin rpy="0 0 0" xyz="0 0 -0.03"/>
      <inertia ixx="6.32e-05" ixy="0.0" ixz="0.0" iyy="6.32e-05" iyz="0.0" izz="6.4e-06"/>
    </inertial>
  </link>
  <gazebo reference="LF_R_phalange">
    <material>Gazebo/Tertiary</material>
  </gazebo>
  <joint name="joint_R_coffin_LF" type="revolute">
    <parent link="LF_R_phalange"/>
    <child link="LF_R_claw"/>
    <origin rpy="0 0 0" xyz="0 0 -0.06"/>
    <axis xyz="0 0 1"/>
    <limit effort="30" lower="-0.25" upper="0.5" velocity="1"/>
    <dynamics damping="0.07" friction="0"/>
  </joint>
  <gazebo reference="joint_R_coffin_LF">
    <implicitSpringDamper>True</implicitSpringDamper>
  </gazebo>
  <gazebo>
    <plugin filename="libsea_plugin.so" name="R_sea_j5">
      <joint>joint_R_coffin_LF</joint>
      <namespace>goat_robot</namespace>
      <stiffness>0.5</stiffness>
      <pub_eltau>true</pub_eltau>
      <pub_state>true</pub_state>
      <sub_ext_tau>true</sub_ext_tau>
    </plugin>
  </gazebo>
  <!-- <xacro:if value="${side == 'R'}">
 <xacro:property name="claw_origin_xyz" value="0 ${phalange_radius/2} 0"/>
 <xacro:property name="mesh_claw" value="package://second_goat_description/meshes/stl/MirrorClaw.stl" />
</xacro:if> 

<xacro:if value="${side == 'L'}">
 <xacro:property name="claw_origin_xyz" value="0 ${-phalange_radius/2} 0"/>
 <xacro:property name="mesh_claw" value="package://second_goat_description/meshes/stl/Claw.stl" />
</xacro:if>  -->
  <link name="LF_R_claw">
    <visual>
      <origin rpy="-1.5707963267948966 0 1.5707963267948966" xyz="0.05 -0.05 0.005"/>
      <geometry>
        <mesh filename="package://second_goat_description/meshes/MirrorClaw.stl" scale="0.0012 0.0012 0.0012"/>
      </geometry>
    </visual>
    <collision>
      <origin rpy="-1.5707963267948966 0 1.5707963267948966" xyz="0.05 -0.05 0.005"/>
      <geometry>
        <mesh filename="package://second_goat_description/meshes/MirrorClaw.stl" scale="0.0012 0.0012 0.0012"/>
      </geometry>
    </collision>
    <inertial>
      <mass value="0.05"/>
      <origin rpy="0 0 0" xyz="0.01 0.004 0"/>
      <inertia ixx="3.759375e-06" ixy="0.0" ixz="0.0" iyy="1.5009375000000002e-05" iyz="0.0" izz="1.875e-05"/>
    </inertial>
  </link>
  <gazebo reference="LF_R_claw">
    <material>Gazebo/Tertiary</material>
  </gazebo>
  <joint name="joint_L_fetlock_RH" type="revolute">
    <parent link="metacarpus_RH"/>
    <child link="RH_L_declaw"/>
    <origin rpy="0 1.5707963267948966 0" xyz="0 -0.015 0"/>
    <axis xyz="0 0 1"/>
    <limit effort="30" lower="-0.04" upper="0.04" velocity="1.0"/>
    <dynamics damping="0.1" friction="0"/>
  </joint>
  <gazebo>
    <plugin filename="libsea_plugin.so" name="L_sea_j3">
      <joint>joint_L_fetlock_RH</joint>
      <namespace>goat_hoof</namespace>
      <stiffness>10</stiffness>
      <pub_eltau>true</pub_eltau>
      <pub_state>true</pub_state>
      <sub_ext_tau>true</sub_ext_tau>
    </plugin>
  </gazebo>
  <link name="RH_L_declaw">
    <visual>
      <origin rpy="0 0 0" xyz="0 0 0"/>
      <geometry>
        <cylinder length="0.02" radius="0.008"/>
      </geometry>
    </visual>
    <collision>
      <origin rpy="0 0 0" xyz="0 0 0"/>
      <geometry>
        <cylinder length="0.02" radius="0.008"/>
      </geometry>
    </collision>
    <inertial>
      <mass value="0.1"/>
      <origin rpy="0 0 0" xyz="0 0 0"/>
      <inertia ixx="4.933333333333334e-06" ixy="0.0" ixz="0.0" iyy="4.933333333333334e-06" iyz="0.0" izz="3.2e-06"/>
    </inertial>
  </link>
  <joint name="joint_L_pastern_RH" type="prismatic">
    <parent link="RH_L_declaw"/>
    <child link="RH_L_phalange"/>
    <origin rpy="0 -1.5707963267948966 0" xyz="0 0 0"/>
    <axis xyz="0 0 1"/>
    <limit effort="30" lower="-0.02" upper="0.02" velocity="1.0"/>
    <dynamics damping="50.0" friction="0"/>
  </joint>
  <gazebo>
    <plugin filename="libsea_plugin.so" name="L_sea_j4">
      <joint>joint_L_pastern_RH</joint>
      <namespace>goat_robot</namespace>
      <stiffness>10000</stiffness>
      <pub_eltau>true</pub_eltau>
      <pub_state>true</pub_state>
      <sub_ext_tau>true</sub_ext_tau>
    </plugin>
  </gazebo>
  <link name="RH_L_phalange">
    <visual>
      <origin rpy="0 0 0" xyz="0 0 -0.03"/>
      <geometry>
        <cylinder length="0.06" radius="0.008"/>
      </geometry>
    </visual>
    <collision>
      <origin rpy="0 0 0" xyz="0 0 -0.03"/>
      <geometry>
        <cylinder length="0.06" radius="0.008"/>
      </geometry>
    </collision>
    <inertial>
      <mass value="0.2"/>
      <origin rpy="0 0 0" xyz="0 0 -0.03"/>
      <inertia ixx="6.32e-05" ixy="0.0" ixz="0.0" iyy="6.32e-05" iyz="0.0" izz="6.4e-06"/>
    </inertial>
  </link>
  <gazebo reference="RH_L_phalange">
    <material>Gazebo/Tertiary</material>
  </gazebo>
  <joint name="joint_L_coffin_RH" type="revolute">
    <parent link="RH_L_phalange"/>
    <child link="RH_L_claw"/>
    <origin rpy="0 0 0" xyz="0 0 -0.06"/>
    <axis xyz="0 0 1"/>
    <limit effort="30" lower="-0.5" upper="0.25" velocity="1"/>
    <dynamics damping="0.07" friction="0"/>
  </joint>
  <gazebo reference="joint_L_coffin_RH">
    <implicitSpringDamper>True</implicitSpringDamper>
  </gazebo>
  <gazebo>
    <plugin filename="libsea_plugin.so" name="L_sea_j5">
      <joint>joint_L_coffin_RH</joint>
      <namespace>goat_robot</namespace>
      <stiffness>0.5</stiffness>
      <pub_eltau>true</pub_eltau>
      <pub_state>true</pub_state>
      <sub_ext_tau>true</sub_ext_tau>
    </plugin>
  </gazebo>
  <!-- <xacro:if value="${side == 'R'}">
 <xacro:property name="claw_origin_xyz" value="0 ${phalange_radius/2} 0"/>
 <xacro:property name="mesh_claw" value="package://second_goat_description/meshes/stl/MirrorClaw.stl" />
</xacro:if> 

<xacro:if value="${side == 'L'}">
 <xacro:property name="claw_origin_xyz" value="0 ${-phalange_radius/2} 0"/>
 <xacro:property name="mesh_claw" value="package://second_goat_description/meshes/stl/Claw.stl" />
</xacro:if>  -->
  <link name="RH_L_claw">
    <visual>
      <origin rpy="-1.5707963267948966 0 1.5707963267948966" xyz="0.05 -0.020 0.005"/>
      <geometry>
        <mesh filename="package://second_goat_description/meshes/Claw.stl" scale="0.0012 0.0012 0.0012"/>
      </geometry>
    </visual>
    <collision>
      <origin rpy="-1.5707963267948966 0 1.5707963267948966" xyz="0.05 -0.020 0.005"/>
      <geometry>
        <mesh filename="package://second_goat_description/meshes/Claw.stl" scale="0.0012 0.0012 0.0012"/>
      </geometry>
    </collision>
    <inertial>
      <mass value="0.05"/>
      <origin rpy="0 0 0" xyz="0.01 -0.004 0"/>
      <inertia ixx="3.759375e-06" ixy="0.0" ixz="0.0" iyy="1.5009375000000002e-05" iyz="0.0" izz="1.875e-05"/>
    </inertial>
  </link>
  <gazebo reference="RH_L_claw">
    <material>Gazebo/Tertiary</material>
  </gazebo>
  <joint name="joint_R_fetlock_RH" type="revolute">
    <parent link="metacarpus_RH"/>
    <child link="RH_R_declaw"/>
    <origin rpy="0 1.5707963267948966 0" xyz="0 0.015 0"/>
    <axis xyz="0 0 1"/>
    <limit effort="30" lower="-0.04" upper="0.04" velocity="1.0"/>
    <dynamics damping="0.1" friction="0"/>
  </joint>
  <gazebo>
    <plugin filename="libsea_plugin.so" name="R_sea_j3">
      <joint>joint_R_fetlock_RH</joint>
      <namespace>goat_hoof</namespace>
      <stiffness>10</stiffness>
      <pub_eltau>true</pub_eltau>
      <pub_state>true</pub_state>
      <sub_ext_tau>true</sub_ext_tau>
    </plugin>
  </gazebo>
  <link name="RH_R_declaw">
    <visual>
      <origin rpy="0 0 0" xyz="0 0 0"/>
      <geometry>
        <cylinder length="0.02" radius="0.008"/>
      </geometry>
    </visual>
    <collision>
      <origin rpy="0 0 0" xyz="0 0 0"/>
      <geometry>
        <cylinder length="0.02" radius="0.008"/>
      </geometry>
    </collision>
    <inertial>
      <mass value="0.1"/>
      <origin rpy="0 0 0" xyz="0 0 0"/>
      <inertia ixx="4.933333333333334e-06" ixy="0.0" ixz="0.0" iyy="4.933333333333334e-06" iyz="0.0" izz="3.2e-06"/>
    </inertial>
  </link>
  <joint name="joint_R_pastern_RH" type="prismatic">
    <parent link="RH_R_declaw"/>
    <child link="RH_R_phalange"/>
    <origin rpy="0 -1.5707963267948966 0" xyz="0 0 0"/>
    <axis xyz="0 0 1"/>
    <limit effort="30" lower="-0.02" upper="0.02" velocity="1.0"/>
    <dynamics damping="50.0" friction="0"/>
  </joint>
  <gazebo>
    <plugin filename="libsea_plugin.so" name="R_sea_j4">
      <joint>joint_R_pastern_RH</joint>
      <namespace>goat_robot</namespace>
      <stiffness>10000</stiffness>
      <pub_eltau>true</pub_eltau>
      <pub_state>true</pub_state>
      <sub_ext_tau>true</sub_ext_tau>
    </plugin>
  </gazebo>
  <link name="RH_R_phalange">
    <visual>
      <origin rpy="0 0 0" xyz="0 0 -0.03"/>
      <geometry>
        <cylinder length="0.06" radius="0.008"/>
      </geometry>
    </visual>
    <collision>
      <origin rpy="0 0 0" xyz="0 0 -0.03"/>
      <geometry>
        <cylinder length="0.06" radius="0.008"/>
      </geometry>
    </collision>
    <inertial>
      <mass value="0.2"/>
      <origin rpy="0 0 0" xyz="0 0 -0.03"/>
      <inertia ixx="6.32e-05" ixy="0.0" ixz="0.0" iyy="6.32e-05" iyz="0.0" izz="6.4e-06"/>
    </inertial>
  </link>
  <gazebo reference="RH_R_phalange">
    <material>Gazebo/Tertiary</material>
  </gazebo>
  <joint name="joint_R_coffin_RH" type="revolute">
    <parent link="RH_R_phalange"/>
    <child link="RH_R_claw"/>
    <origin rpy="0 0 0" xyz="0 0 -0.06"/>
    <axis xyz="0 0 1"/>
    <limit effort="30" lower="-0.25" upper="0.5" velocity="1"/>
    <dynamics damping="0.07" friction="0"/>
  </joint>
  <gazebo reference="joint_R_coffin_RH">
    <implicitSpringDamper>True</implicitSpringDamper>
  </gazebo>
  <gazebo>
    <plugin filename="libsea_plugin.so" name="R_sea_j5">
      <joint>joint_R_coffin_RH</joint>
      <namespace>goat_robot</namespace>
      <stiffness>0.5</stiffness>
      <pub_eltau>true</pub_eltau>
      <pub_state>true</pub_state>
      <sub_ext_tau>true</sub_ext_tau>
    </plugin>
  </gazebo>
  <!-- <xacro:if value="${side == 'R'}">
 <xacro:property name="claw_origin_xyz" value="0 ${phalange_radius/2} 0"/>
 <xacro:property name="mesh_claw" value="package://second_goat_description/meshes/stl/MirrorClaw.stl" />
</xacro:if> 

<xacro:if value="${side == 'L'}">
 <xacro:property name="claw_origin_xyz" value="0 ${-phalange_radius/2} 0"/>
 <xacro:property name="mesh_claw" value="package://second_goat_description/meshes/stl/Claw.stl" />
</xacro:if>  -->
  <link name="RH_R_claw">
    <visual>
      <origin rpy="-1.5707963267948966 0 1.5707963267948966" xyz="0.05 -0.05 0.005"/>
      <geometry>
        <mesh filename="package://second_goat_description/meshes/MirrorClaw.stl" scale="0.0012 0.0012 0.0012"/>
      </geometry>
    </visual>
    <collision>
      <origin rpy="-1.5707963267948966 0 1.5707963267948966" xyz="0.05 -0.05 0.005"/>
      <geometry>
        <mesh filename="package://second_goat_description/meshes/MirrorClaw.stl" scale="0.0012 0.0012 0.0012"/>
      </geometry>
    </collision>
    <inertial>
      <mass value="0.05"/>
      <origin rpy="0 0 0" xyz="0.01 0.004 0"/>
      <inertia ixx="3.759375e-06" ixy="0.0" ixz="0.0" iyy="1.5009375000000002e-05" iyz="0.0" izz="1.875e-05"/>
    </inertial>
  </link>
  <gazebo reference="RH_R_claw">
    <material>Gazebo/Tertiary</material>
  </gazebo>
  <joint name="joint_L_fetlock_LH" type="revolute">
    <parent link="metacarpus_LH"/>
    <child link="LH_L_declaw"/>
    <origin rpy="0 1.5707963267948966 0" xyz="0 -0.015 0"/>
    <axis xyz="0 0 1"/>
    <limit effort="30" lower="-0.04" upper="0.04" velocity="1.0"/>
    <dynamics damping="0.1" friction="0"/>
  </joint>
  <gazebo>
    <plugin filename="libsea_plugin.so" name="L_sea_j3">
      <joint>joint_L_fetlock_LH</joint>
      <namespace>goat_hoof</namespace>
      <stiffness>10</stiffness>
      <pub_eltau>true</pub_eltau>
      <pub_state>true</pub_state>
      <sub_ext_tau>true</sub_ext_tau>
    </plugin>
  </gazebo>
  <link name="LH_L_declaw">
    <visual>
      <origin rpy="0 0 0" xyz="0 0 0"/>
      <geometry>
        <cylinder length="0.02" radius="0.008"/>
      </geometry>
    </visual>
    <collision>
      <origin rpy="0 0 0" xyz="0 0 0"/>
      <geometry>
        <cylinder length="0.02" radius="0.008"/>
      </geometry>
    </collision>
    <inertial>
      <mass value="0.1"/>
      <origin rpy="0 0 0" xyz="0 0 0"/>
      <inertia ixx="4.933333333333334e-06" ixy="0.0" ixz="0.0" iyy="4.933333333333334e-06" iyz="0.0" izz="3.2e-06"/>
    </inertial>
  </link>
  <joint name="joint_L_pastern_LH" type="prismatic">
    <parent link="LH_L_declaw"/>
    <child link="LH_L_phalange"/>
    <origin rpy="0 -1.5707963267948966 0" xyz="0 0 0"/>
    <axis xyz="0 0 1"/>
    <limit effort="30" lower="-0.02" upper="0.02" velocity="1.0"/>
    <dynamics damping="50.0" friction="0"/>
  </joint>
  <gazebo>
    <plugin filename="libsea_plugin.so" name="L_sea_j4">
      <joint>joint_L_pastern_LH</joint>
      <namespace>goat_robot</namespace>
      <stiffness>10000</stiffness>
      <pub_eltau>true</pub_eltau>
      <pub_state>true</pub_state>
      <sub_ext_tau>true</sub_ext_tau>
    </plugin>
  </gazebo>
  <link name="LH_L_phalange">
    <visual>
      <origin rpy="0 0 0" xyz="0 0 -0.03"/>
      <geometry>
        <cylinder length="0.06" radius="0.008"/>
      </geometry>
    </visual>
    <collision>
      <origin rpy="0 0 0" xyz="0 0 -0.03"/>
      <geometry>
        <cylinder length="0.06" radius="0.008"/>
      </geometry>
    </collision>
    <inertial>
      <mass value="0.2"/>
      <origin rpy="0 0 0" xyz="0 0 -0.03"/>
      <inertia ixx="6.32e-05" ixy="0.0" ixz="0.0" iyy="6.32e-05" iyz="0.0" izz="6.4e-06"/>
    </inertial>
  </link>
  <gazebo reference="LH_L_phalange">
    <material>Gazebo/Tertiary</material>
  </gazebo>
  <joint name="joint_L_coffin_LH" type="revolute">
    <parent link="LH_L_phalange"/>
    <child link="LH_L_claw"/>
    <origin rpy="0 0 0" xyz="0 0 -0.06"/>
    <axis xyz="0 0 1"/>
    <limit effort="30" lower="-0.5" upper="0.25" velocity="1"/>
    <dynamics damping="0.07" friction="0"/>
  </joint>
  <gazebo reference="joint_L_coffin_LH">
    <implicitSpringDamper>True</implicitSpringDamper>
  </gazebo>
  <gazebo>
    <plugin filename="libsea_plugin.so" name="L_sea_j5">
      <joint>joint_L_coffin_LH</joint>
      <namespace>goat_robot</namespace>
      <stiffness>0.5</stiffness>
      <pub_eltau>true</pub_eltau>
      <pub_state>true</pub_state>
      <sub_ext_tau>true</sub_ext_tau>
    </plugin>
  </gazebo>
  <!-- <xacro:if value="${side == 'R'}">
 <xacro:property name="claw_origin_xyz" value="0 ${phalange_radius/2} 0"/>
 <xacro:property name="mesh_claw" value="package://second_goat_description/meshes/stl/MirrorClaw.stl" />
</xacro:if> 

<xacro:if value="${side == 'L'}">
 <xacro:property name="claw_origin_xyz" value="0 ${-phalange_radius/2} 0"/>
 <xacro:property name="mesh_claw" value="package://second_goat_description/meshes/stl/Claw.stl" />
</xacro:if>  -->
  <link name="LH_L_claw">
    <visual>
      <origin rpy="-1.5707963267948966 0 1.5707963267948966" xyz="0.05 -0.020 0.005"/>
      <geometry>
        <mesh filename="package://second_goat_description/meshes/Claw.stl" scale="0.0012 0.0012 0.0012"/>
      </geometry>
    </visual>
    <collision>
      <origin rpy="-1.5707963267948966 0 1.5707963267948966" xyz="0.05 -0.020 0.005"/>
      <geometry>
        <mesh filename="package://second_goat_description/meshes/Claw.stl" scale="0.0012 0.0012 0.0012"/>
      </geometry>
    </collision>
    <inertial>
      <mass value="0.05"/>
      <origin rpy="0 0 0" xyz="0.01 -0.004 0"/>
      <inertia ixx="3.759375e-06" ixy="0.0" ixz="0.0" iyy="1.5009375000000002e-05" iyz="0.0" izz="1.875e-05"/>
    </inertial>
  </link>
  <gazebo reference="LH_L_claw">
    <material>Gazebo/Tertiary</material>
  </gazebo>
  <joint name="joint_R_fetlock_LH" type="revolute">
    <parent link="metacarpus_LH"/>
    <child link="LH_R_declaw"/>
    <origin rpy="0 1.5707963267948966 0" xyz="0 0.015 0"/>
    <axis xyz="0 0 1"/>
    <limit effort="30" lower="-0.04" upper="0.04" velocity="1.0"/>
    <dynamics damping="0.1" friction="0"/>
  </joint>
  <gazebo>
    <plugin filename="libsea_plugin.so" name="R_sea_j3">
      <joint>joint_R_fetlock_LH</joint>
      <namespace>goat_hoof</namespace>
      <stiffness>10</stiffness>
      <pub_eltau>true</pub_eltau>
      <pub_state>true</pub_state>
      <sub_ext_tau>true</sub_ext_tau>
    </plugin>
  </gazebo>
  <link name="LH_R_declaw">
    <visual>
      <origin rpy="0 0 0" xyz="0 0 0"/>
      <geometry>
        <cylinder length="0.02" radius="0.008"/>
      </geometry>
    </visual>
    <collision>
      <origin rpy="0 0 0" xyz="0 0 0"/>
      <geometry>
        <cylinder length="0.02" radius="0.008"/>
      </geometry>
    </collision>
    <inertial>
      <mass value="0.1"/>
      <origin rpy="0 0 0" xyz="0 0 0"/>
      <inertia ixx="4.933333333333334e-06" ixy="0.0" ixz="0.0" iyy="4.933333333333334e-06" iyz="0.0" izz="3.2e-06"/>
    </inertial>
  </link>
  <joint name="joint_R_pastern_LH" type="prismatic">
    <parent link="LH_R_declaw"/>
    <child link="LH_R_phalange"/>
    <origin rpy="0 -1.5707963267948966 0" xyz="0 0 0"/>
    <axis xyz="0 0 1"/>
    <limit effort="30" lower="-0.02" upper="0.02" velocity="1.0"/>
    <dynamics damping="50.0" friction="0"/>
  </joint>
  <gazebo>
    <plugin filename="libsea_plugin.so" name="R_sea_j4">
      <joint>joint_R_pastern_LH</joint>
      <namespace>goat_robot</namespace>
      <stiffness>10000</stiffness>
      <pub_eltau>true</pub_eltau>
      <pub_state>true</pub_state>
      <sub_ext_tau>true</sub_ext_tau>
    </plugin>
  </gazebo>
  <link name="LH_R_phalange">
    <visual>
      <origin rpy="0 0 0" xyz="0 0 -0.03"/>
      <geometry>
        <cylinder length="0.06" radius="0.008"/>
      </geometry>
    </visual>
    <collision>
      <origin rpy="0 0 0" xyz="0 0 -0.03"/>
      <geometry>
        <cylinder length="0.06" radius="0.008"/>
      </geometry>
    </collision>
    <inertial>
      <mass value="0.2"/>
      <origin rpy="0 0 0" xyz="0 0 -0.03"/>
      <inertia ixx="6.32e-05" ixy="0.0" ixz="0.0" iyy="6.32e-05" iyz="0.0" izz="6.4e-06"/>
    </inertial>
  </link>
  <gazebo reference="LH_R_phalange">
    <material>Gazebo/Tertiary</material>
  </gazebo>
  <joint name="joint_R_coffin_LH" type="revolute">
    <parent link="LH_R_phalange"/>
    <child link="LH_R_claw"/>
    <origin rpy="0 0 0" xyz="0 0 -0.06"/>
    <axis xyz="0 0 1"/>
    <limit effort="30" lower="-0.25" upper="0.5" velocity="1"/>
    <dynamics damping="0.07" friction="0"/>
  </joint>
  <gazebo reference="joint_R_coffin_LH">
    <implicitSpringDamper>True</implicitSpringDamper>
  </gazebo>
  <gazebo>
    <plugin filename="libsea_plugin.so" name="R_sea_j5">
      <joint>joint_R_coffin_LH</joint>
      <namespace>goat_robot</namespace>
      <stiffness>0.5</stiffness>
      <pub_eltau>true</pub_eltau>
      <pub_state>true</pub_state>
      <sub_ext_tau>true</sub_ext_tau>
    </plugin>
  </gazebo>
  <!-- <xacro:if value="${side == 'R'}">
 <xacro:property name="claw_origin_xyz" value="0 ${phalange_radius/2} 0"/>
 <xacro:property name="mesh_claw" value="package://second_goat_description/meshes/stl/MirrorClaw.stl" />
</xacro:if> 

<xacro:if value="${side == 'L'}">
 <xacro:property name="claw_origin_xyz" value="0 ${-phalange_radius/2} 0"/>
 <xacro:property name="mesh_claw" value="package://second_goat_description/meshes/stl/Claw.stl" />
</xacro:if>  -->
  <link name="LH_R_claw">
    <visual>
      <origin rpy="-1.5707963267948966 0 1.5707963267948966" xyz="0.05 -0.05 0.005"/>
      <geometry>
        <mesh filename="package://second_goat_description/meshes/MirrorClaw.stl" scale="0.0012 0.0012 0.0012"/>
      </geometry>
    </visual>
    <collision>
      <origin rpy="-1.5707963267948966 0 1.5707963267948966" xyz="0.05 -0.05 0.005"/>
      <geometry>
        <mesh filename="package://second_goat_description/meshes/MirrorClaw.stl" scale="0.0012 0.0012 0.0012"/>
      </geometry>
    </collision>
    <inertial>
      <mass value="0.05"/>
      <origin rpy="0 0 0" xyz="0.01 0.004 0"/>
      <inertia ixx="3.759375e-06" ixy="0.0" ixz="0.0" iyy="1.5009375000000002e-05" iyz="0.0" izz="1.875e-05"/>
    </inertial>
  </link>
  <gazebo reference="LH_R_claw">
    <material>Gazebo/Tertiary</material>
  </gazebo>

   <!-- Trans LF -->  
    <transmission name="tran_1">
    <type>transmission_interface/SimpleTransmission</type>
    <joint name="LF_hip_joint">
      <hardwareInterface>hardware_interface/EffortJointInterface</hardwareInterface>
    </joint>
    <actuator name="motor_1">
      <hardwareInterface>hardware_interface/EffortJointInterface</hardwareInterface>
      <mechanicalReduction>1</mechanicalReduction>
    </actuator>
  </transmission>
    <transmission name="tran_2">
    <type>transmission_interface/SimpleTransmission</type>
    <joint name="LF_knee_joint">
      <hardwareInterface>hardware_interface/EffortJointInterface</hardwareInterface>
    </joint>
    <actuator name="motor_2">
      <hardwareInterface>hardware_interface/EffortJointInterface</hardwareInterface>
      <mechanicalReduction>1</mechanicalReduction>
    </actuator>
  </transmission>
  
   <!-- Trans RF --> 
  
  <transmission name="tran_4">
    <type>transmission_interface/SimpleTransmission</type>
    <joint name="RF_hip_joint">
      <hardwareInterface>hardware_interface/EffortJointInterface</hardwareInterface>
    </joint>
    <actuator name="motor_4">
      <hardwareInterface>hardware_interface/EffortJointInterface</hardwareInterface>
      <mechanicalReduction>1</mechanicalReduction>
    </actuator>
  </transmission>
    <transmission name="tran_5">
    <type>transmission_interface/SimpleTransmission</type>
    <joint name="RF_knee_joint">
      <hardwareInterface>hardware_interface/EffortJointInterface</hardwareInterface>
    </joint>
    <actuator name="motor_5">
      <hardwareInterface>hardware_interface/EffortJointInterface</hardwareInterface>
      <mechanicalReduction>1</mechanicalReduction>
    </actuator>
  </transmission>
  
    <!-- Trans LH --> 
  
  <transmission name="tran_7">
    <type>transmission_interface/SimpleTransmission</type>
    <joint name="LH_hip_joint">
      <hardwareInterface>hardware_interface/EffortJointInterface</hardwareInterface>
    </joint>
    <actuator name="motor_7">
      <hardwareInterface>hardware_interface/EffortJointInterface</hardwareInterface>
      <mechanicalReduction>1</mechanicalReduction>
    </actuator>
  </transmission>
    <transmission name="tran_8">
    <type>transmission_interface/SimpleTransmission</type>
    <joint name="LH_knee_joint">
      <hardwareInterface>hardware_interface/EffortJointInterface</hardwareInterface>
    </joint>
    <actuator name="motor_8">
      <hardwareInterface>hardware_interface/EffortJointInterface</hardwareInterface>
      <mechanicalReduction>1</mechanicalReduction>
    </actuator>
  </transmission>
  
     <!-- Trans RH --> 
  
  <transmission name="tran_10">
    <type>transmission_interface/SimpleTransmission</type>
    <joint name="RH_hip_joint">
      <hardwareInterface>hardware_interface/EffortJointInterface</hardwareInterface>
    </joint>
    <actuator name="motor_10">
      <hardwareInterface>hardware_interface/EffortJointInterface</hardwareInterface>
      <mechanicalReduction>1</mechanicalReduction>
    </actuator>
  </transmission>
    <transmission name="tran_11">
    <type>transmission_interface/SimpleTransmission</type>
    <joint name="RH_knee_joint">
      <hardwareInterface>hardware_interface/EffortJointInterface</hardwareInterface>
    </joint>
    <actuator name="motor_11">
      <hardwareInterface>hardware_interface/EffortJointInterface</hardwareInterface>
      <mechanicalReduction>1</mechanicalReduction>
    </actuator>
  </transmission>
  
  
  
</robot>
